[2024-12-10T11:00:42.073-0300] {local_task_job_runner.py:120} INFO - ::group::Pre task execution logs
[2024-12-10T11:00:42.080-0300] {taskinstance.py:2073} INFO - Dependencies all met for dep_context=non-requeueable deps ti=<TaskInstance: medallion_architecture.passo1 scheduled__2024-12-09T00:00:00+00:00 [queued]>
[2024-12-10T11:00:42.084-0300] {taskinstance.py:2073} INFO - Dependencies all met for dep_context=requeueable deps ti=<TaskInstance: medallion_architecture.passo1 scheduled__2024-12-09T00:00:00+00:00 [queued]>
[2024-12-10T11:00:42.084-0300] {taskinstance.py:2303} INFO - Starting attempt 1 of 1
[2024-12-10T11:00:42.096-0300] {taskinstance.py:2327} INFO - Executing <Task(PythonOperator): passo1> on 2024-12-09 00:00:00+00:00
[2024-12-10T11:00:42.100-0300] {standard_task_runner.py:63} INFO - Started process 18950 to run task
[2024-12-10T11:00:42.100-0300] {clientserver.py:543} INFO - Closing down clientserver connection
[2024-12-10T11:00:42.104-0300] {standard_task_runner.py:90} INFO - Running: ['airflow', 'tasks', 'run', 'medallion_architecture', 'passo1', 'scheduled__2024-12-09T00:00:00+00:00', '--job-id', '18', '--raw', '--subdir', 'DAGS_FOLDER/dag2.py', '--cfg-path', '/tmp/tmpqxdfl1l_']
[2024-12-10T11:00:42.105-0300] {standard_task_runner.py:91} INFO - Job 18: Subtask passo1
[2024-12-10T11:00:42.134-0300] {task_command.py:426} INFO - Running <TaskInstance: medallion_architecture.passo1 scheduled__2024-12-09T00:00:00+00:00 [running]> on host beatriz-linux
[2024-12-10T11:00:42.190-0300] {taskinstance.py:2644} INFO - Exporting env vars: AIRFLOW_CTX_DAG_OWNER='airflow' AIRFLOW_CTX_DAG_ID='medallion_architecture' AIRFLOW_CTX_TASK_ID='passo1' AIRFLOW_CTX_EXECUTION_DATE='2024-12-09T00:00:00+00:00' AIRFLOW_CTX_TRY_NUMBER='1' AIRFLOW_CTX_DAG_RUN_ID='scheduled__2024-12-09T00:00:00+00:00'
[2024-12-10T11:00:42.191-0300] {taskinstance.py:430} INFO - ::endgroup::
[2024-12-10T11:00:43.140-0300] {taskinstance.py:441} INFO - ::group::Post task execution logs
[2024-12-10T11:00:43.140-0300] {taskinstance.py:2890} ERROR - Task failed with exception
Traceback (most recent call last):
  File "/home/beatriz/Documentos/airflow/airflow_venv/lib/python3.10/site-packages/airflow/models/taskinstance.py", line 465, in _execute_task
    result = _execute_callable(context=context, **execute_callable_kwargs)
  File "/home/beatriz/Documentos/airflow/airflow_venv/lib/python3.10/site-packages/airflow/models/taskinstance.py", line 432, in _execute_callable
    return execute_callable(context=context, **execute_callable_kwargs)
  File "/home/beatriz/Documentos/airflow/airflow_venv/lib/python3.10/site-packages/airflow/models/baseoperator.py", line 400, in wrapper
    return func(self, *args, **kwargs)
  File "/home/beatriz/Documentos/airflow/airflow_venv/lib/python3.10/site-packages/airflow/operators/python.py", line 235, in execute
    return_value = self.execute_callable()
  File "/home/beatriz/Documentos/airflow/airflow_venv/lib/python3.10/site-packages/airflow/operators/python.py", line 252, in execute_callable
    return self.python_callable(*self.op_args, **self.op_kwargs)
  File "/home/beatriz/Documentos/airflow/dags/tarefas/tarefas.py", line 46, in passo1_bronze
    table1_customers = spark.read.json(landing_customers_path)
  File "/home/beatriz/Documentos/airflow/airflow_venv/lib/python3.10/site-packages/pyspark/sql/readwriter.py", line 425, in json
    return self._df(self._jreader.json(self._spark._sc._jvm.PythonUtils.toSeq(path)))
  File "/home/beatriz/Documentos/airflow/airflow_venv/lib/python3.10/site-packages/py4j/java_gateway.py", line 1322, in __call__
    return_value = get_return_value(
  File "/home/beatriz/Documentos/airflow/airflow_venv/lib/python3.10/site-packages/pyspark/errors/exceptions/captured.py", line 179, in deco
    return f(*a, **kw)
  File "/home/beatriz/Documentos/airflow/airflow_venv/lib/python3.10/site-packages/py4j/protocol.py", line 326, in get_return_value
    raise Py4JJavaError(
py4j.protocol.Py4JJavaError: An error occurred while calling o29.json.
: java.lang.RuntimeException: java.lang.ClassNotFoundException: Class org.apache.hadoop.fs.s3a.S3AFileSystem not found
	at org.apache.hadoop.conf.Configuration.getClass(Configuration.java:2688)
	at org.apache.hadoop.fs.FileSystem.getFileSystemClass(FileSystem.java:3431)
	at org.apache.hadoop.fs.FileSystem.createFileSystem(FileSystem.java:3466)
	at org.apache.hadoop.fs.FileSystem.access$300(FileSystem.java:174)
	at org.apache.hadoop.fs.FileSystem$Cache.getInternal(FileSystem.java:3574)
	at org.apache.hadoop.fs.FileSystem$Cache.get(FileSystem.java:3521)
	at org.apache.hadoop.fs.FileSystem.get(FileSystem.java:540)
	at org.apache.hadoop.fs.Path.getFileSystem(Path.java:365)
	at org.apache.spark.sql.execution.datasources.DataSource$.$anonfun$checkAndGlobPathIfNecessary$1(DataSource.scala:724)
	at scala.collection.immutable.List.map(List.scala:293)
	at org.apache.spark.sql.execution.datasources.DataSource$.checkAndGlobPathIfNecessary(DataSource.scala:722)
	at org.apache.spark.sql.execution.datasources.DataSource.checkAndGlobPathIfNecessary(DataSource.scala:551)
	at org.apache.spark.sql.execution.datasources.DataSource.resolveRelation(DataSource.scala:404)
	at org.apache.spark.sql.DataFrameReader.loadV1Source(DataFrameReader.scala:229)
	at org.apache.spark.sql.DataFrameReader.$anonfun$load$2(DataFrameReader.scala:211)
	at scala.Option.getOrElse(Option.scala:189)
	at org.apache.spark.sql.DataFrameReader.load(DataFrameReader.scala:211)
	at org.apache.spark.sql.DataFrameReader.json(DataFrameReader.scala:362)
	at java.base/jdk.internal.reflect.NativeMethodAccessorImpl.invoke0(Native Method)
	at java.base/jdk.internal.reflect.NativeMethodAccessorImpl.invoke(NativeMethodAccessorImpl.java:62)
	at java.base/jdk.internal.reflect.DelegatingMethodAccessorImpl.invoke(DelegatingMethodAccessorImpl.java:43)
	at java.base/java.lang.reflect.Method.invoke(Method.java:566)
	at py4j.reflection.MethodInvoker.invoke(MethodInvoker.java:244)
	at py4j.reflection.ReflectionEngine.invoke(ReflectionEngine.java:374)
	at py4j.Gateway.invoke(Gateway.java:282)
	at py4j.commands.AbstractCommand.invokeMethod(AbstractCommand.java:132)
	at py4j.commands.CallCommand.execute(CallCommand.java:79)
	at py4j.ClientServerConnection.waitForCommands(ClientServerConnection.java:182)
	at py4j.ClientServerConnection.run(ClientServerConnection.java:106)
	at java.base/java.lang.Thread.run(Thread.java:829)
Caused by: java.lang.ClassNotFoundException: Class org.apache.hadoop.fs.s3a.S3AFileSystem not found
	at org.apache.hadoop.conf.Configuration.getClassByName(Configuration.java:2592)
	at org.apache.hadoop.conf.Configuration.getClass(Configuration.java:2686)
	... 29 more

[2024-12-10T11:00:43.147-0300] {taskinstance.py:1205} INFO - Marking task as FAILED. dag_id=medallion_architecture, task_id=passo1, execution_date=20241209T000000, start_date=20241210T140042, end_date=20241210T140043
[2024-12-10T11:00:43.157-0300] {standard_task_runner.py:110} ERROR - Failed to execute job 18 for task passo1 (An error occurred while calling o29.json.
: java.lang.RuntimeException: java.lang.ClassNotFoundException: Class org.apache.hadoop.fs.s3a.S3AFileSystem not found
	at org.apache.hadoop.conf.Configuration.getClass(Configuration.java:2688)
	at org.apache.hadoop.fs.FileSystem.getFileSystemClass(FileSystem.java:3431)
	at org.apache.hadoop.fs.FileSystem.createFileSystem(FileSystem.java:3466)
	at org.apache.hadoop.fs.FileSystem.access$300(FileSystem.java:174)
	at org.apache.hadoop.fs.FileSystem$Cache.getInternal(FileSystem.java:3574)
	at org.apache.hadoop.fs.FileSystem$Cache.get(FileSystem.java:3521)
	at org.apache.hadoop.fs.FileSystem.get(FileSystem.java:540)
	at org.apache.hadoop.fs.Path.getFileSystem(Path.java:365)
	at org.apache.spark.sql.execution.datasources.DataSource$.$anonfun$checkAndGlobPathIfNecessary$1(DataSource.scala:724)
	at scala.collection.immutable.List.map(List.scala:293)
	at org.apache.spark.sql.execution.datasources.DataSource$.checkAndGlobPathIfNecessary(DataSource.scala:722)
	at org.apache.spark.sql.execution.datasources.DataSource.checkAndGlobPathIfNecessary(DataSource.scala:551)
	at org.apache.spark.sql.execution.datasources.DataSource.resolveRelation(DataSource.scala:404)
	at org.apache.spark.sql.DataFrameReader.loadV1Source(DataFrameReader.scala:229)
	at org.apache.spark.sql.DataFrameReader.$anonfun$load$2(DataFrameReader.scala:211)
	at scala.Option.getOrElse(Option.scala:189)
	at org.apache.spark.sql.DataFrameReader.load(DataFrameReader.scala:211)
	at org.apache.spark.sql.DataFrameReader.json(DataFrameReader.scala:362)
	at java.base/jdk.internal.reflect.NativeMethodAccessorImpl.invoke0(Native Method)
	at java.base/jdk.internal.reflect.NativeMethodAccessorImpl.invoke(NativeMethodAccessorImpl.java:62)
	at java.base/jdk.internal.reflect.DelegatingMethodAccessorImpl.invoke(DelegatingMethodAccessorImpl.java:43)
	at java.base/java.lang.reflect.Method.invoke(Method.java:566)
	at py4j.reflection.MethodInvoker.invoke(MethodInvoker.java:244)
	at py4j.reflection.ReflectionEngine.invoke(ReflectionEngine.java:374)
	at py4j.Gateway.invoke(Gateway.java:282)
	at py4j.commands.AbstractCommand.invokeMethod(AbstractCommand.java:132)
	at py4j.commands.CallCommand.execute(CallCommand.java:79)
	at py4j.ClientServerConnection.waitForCommands(ClientServerConnection.java:182)
	at py4j.ClientServerConnection.run(ClientServerConnection.java:106)
	at java.base/java.lang.Thread.run(Thread.java:829)
Caused by: java.lang.ClassNotFoundException: Class org.apache.hadoop.fs.s3a.S3AFileSystem not found
	at org.apache.hadoop.conf.Configuration.getClassByName(Configuration.java:2592)
	at org.apache.hadoop.conf.Configuration.getClass(Configuration.java:2686)
	... 29 more
; 18950)
[2024-12-10T11:00:43.197-0300] {local_task_job_runner.py:240} INFO - Task exited with return code 1
[2024-12-10T11:00:43.214-0300] {taskinstance.py:3482} INFO - 0 downstream tasks scheduled from follow-on schedule check
[2024-12-10T11:00:43.222-0300] {local_task_job_runner.py:222} INFO - ::endgroup::
