[2024-12-11T18:39:22.257-0300] {local_task_job_runner.py:120} INFO - ::group::Pre task execution logs
[2024-12-11T18:39:22.266-0300] {taskinstance.py:2073} INFO - Dependencies all met for dep_context=non-requeueable deps ti=<TaskInstance: medallion_architecture.passo1 manual__2024-12-11T21:39:13.871205+00:00 [queued]>
[2024-12-11T18:39:22.271-0300] {taskinstance.py:2073} INFO - Dependencies all met for dep_context=requeueable deps ti=<TaskInstance: medallion_architecture.passo1 manual__2024-12-11T21:39:13.871205+00:00 [queued]>
[2024-12-11T18:39:22.272-0300] {taskinstance.py:2303} INFO - Starting attempt 1 of 1
[2024-12-11T18:39:22.286-0300] {taskinstance.py:2327} INFO - Executing <Task(PythonOperator): passo1> on 2024-12-11 21:39:13.871205+00:00
[2024-12-11T18:39:22.291-0300] {clientserver.py:543} INFO - Closing down clientserver connection
[2024-12-11T18:39:22.291-0300] {standard_task_runner.py:63} INFO - Started process 51305 to run task
[2024-12-11T18:39:22.296-0300] {standard_task_runner.py:90} INFO - Running: ['airflow', 'tasks', 'run', 'medallion_architecture', 'passo1', 'manual__2024-12-11T21:39:13.871205+00:00', '--job-id', '80', '--raw', '--subdir', 'DAGS_FOLDER/dag2.py', '--cfg-path', '/tmp/tmpu0es58bt']
[2024-12-11T18:39:22.297-0300] {standard_task_runner.py:91} INFO - Job 80: Subtask passo1
[2024-12-11T18:39:22.334-0300] {task_command.py:426} INFO - Running <TaskInstance: medallion_architecture.passo1 manual__2024-12-11T21:39:13.871205+00:00 [running]> on host beatriz-linux
[2024-12-11T18:39:22.397-0300] {taskinstance.py:2644} INFO - Exporting env vars: AIRFLOW_CTX_DAG_OWNER='airflow' AIRFLOW_CTX_DAG_ID='medallion_architecture' AIRFLOW_CTX_TASK_ID='passo1' AIRFLOW_CTX_EXECUTION_DATE='2024-12-11T21:39:13.871205+00:00' AIRFLOW_CTX_TRY_NUMBER='1' AIRFLOW_CTX_DAG_RUN_ID='manual__2024-12-11T21:39:13.871205+00:00'
[2024-12-11T18:39:22.398-0300] {taskinstance.py:430} INFO - ::endgroup::
[2024-12-11T18:39:27.854-0300] {taskinstance.py:441} INFO - ::group::Post task execution logs
[2024-12-11T18:39:27.855-0300] {taskinstance.py:2890} ERROR - Task failed with exception
Traceback (most recent call last):
  File "/home/beatriz/Documentos/airflow/airflow_venv/lib/python3.10/site-packages/airflow/models/taskinstance.py", line 465, in _execute_task
    result = _execute_callable(context=context, **execute_callable_kwargs)
  File "/home/beatriz/Documentos/airflow/airflow_venv/lib/python3.10/site-packages/airflow/models/taskinstance.py", line 432, in _execute_callable
    return execute_callable(context=context, **execute_callable_kwargs)
  File "/home/beatriz/Documentos/airflow/airflow_venv/lib/python3.10/site-packages/airflow/models/baseoperator.py", line 400, in wrapper
    return func(self, *args, **kwargs)
  File "/home/beatriz/Documentos/airflow/airflow_venv/lib/python3.10/site-packages/airflow/operators/python.py", line 235, in execute
    return_value = self.execute_callable()
  File "/home/beatriz/Documentos/airflow/airflow_venv/lib/python3.10/site-packages/airflow/operators/python.py", line 252, in execute_callable
    return self.python_callable(*self.op_args, **self.op_kwargs)
  File "/home/beatriz/Documentos/airflow/dags/tarefas/tarefas.py", line 35, in passo1_bronze
    table1_customers.coalesce(1).write.mode("overwrite").parquet(bronze_customers_path)
  File "/home/beatriz/Documentos/airflow/airflow_venv/lib/python3.10/site-packages/pyspark/sql/readwriter.py", line 1721, in parquet
    self._jwrite.parquet(path)
  File "/home/beatriz/Documentos/airflow/airflow_venv/lib/python3.10/site-packages/py4j/java_gateway.py", line 1322, in __call__
    return_value = get_return_value(
  File "/home/beatriz/Documentos/airflow/airflow_venv/lib/python3.10/site-packages/pyspark/errors/exceptions/captured.py", line 179, in deco
    return f(*a, **kw)
  File "/home/beatriz/Documentos/airflow/airflow_venv/lib/python3.10/site-packages/py4j/protocol.py", line 326, in get_return_value
    raise Py4JJavaError(
py4j.protocol.Py4JJavaError: An error occurred while calling o42.parquet.
: java.lang.RuntimeException: java.lang.ClassNotFoundException: Class org.apache.hadoop.fs.s3a.S3AFileSystem not found
	at org.apache.hadoop.conf.Configuration.getClass(Configuration.java:2688)
	at org.apache.hadoop.fs.FileSystem.getFileSystemClass(FileSystem.java:3431)
	at org.apache.hadoop.fs.FileSystem.createFileSystem(FileSystem.java:3466)
	at org.apache.hadoop.fs.FileSystem.access$300(FileSystem.java:174)
	at org.apache.hadoop.fs.FileSystem$Cache.getInternal(FileSystem.java:3574)
	at org.apache.hadoop.fs.FileSystem$Cache.get(FileSystem.java:3521)
	at org.apache.hadoop.fs.FileSystem.get(FileSystem.java:540)
	at org.apache.hadoop.fs.Path.getFileSystem(Path.java:365)
	at org.apache.spark.sql.execution.datasources.DataSource.planForWritingFileFormat(DataSource.scala:454)
	at org.apache.spark.sql.execution.datasources.DataSource.planForWriting(DataSource.scala:530)
	at org.apache.spark.sql.DataFrameWriter.saveToV1Source(DataFrameWriter.scala:391)
	at org.apache.spark.sql.DataFrameWriter.saveInternal(DataFrameWriter.scala:364)
	at org.apache.spark.sql.DataFrameWriter.save(DataFrameWriter.scala:243)
	at org.apache.spark.sql.DataFrameWriter.parquet(DataFrameWriter.scala:802)
	at java.base/jdk.internal.reflect.NativeMethodAccessorImpl.invoke0(Native Method)
	at java.base/jdk.internal.reflect.NativeMethodAccessorImpl.invoke(NativeMethodAccessorImpl.java:62)
	at java.base/jdk.internal.reflect.DelegatingMethodAccessorImpl.invoke(DelegatingMethodAccessorImpl.java:43)
	at java.base/java.lang.reflect.Method.invoke(Method.java:566)
	at py4j.reflection.MethodInvoker.invoke(MethodInvoker.java:244)
	at py4j.reflection.ReflectionEngine.invoke(ReflectionEngine.java:374)
	at py4j.Gateway.invoke(Gateway.java:282)
	at py4j.commands.AbstractCommand.invokeMethod(AbstractCommand.java:132)
	at py4j.commands.CallCommand.execute(CallCommand.java:79)
	at py4j.ClientServerConnection.waitForCommands(ClientServerConnection.java:182)
	at py4j.ClientServerConnection.run(ClientServerConnection.java:106)
	at java.base/java.lang.Thread.run(Thread.java:829)
Caused by: java.lang.ClassNotFoundException: Class org.apache.hadoop.fs.s3a.S3AFileSystem not found
	at org.apache.hadoop.conf.Configuration.getClassByName(Configuration.java:2592)
	at org.apache.hadoop.conf.Configuration.getClass(Configuration.java:2686)
	... 25 more

[2024-12-11T18:39:27.863-0300] {taskinstance.py:1205} INFO - Marking task as FAILED. dag_id=medallion_architecture, task_id=passo1, execution_date=20241211T213913, start_date=20241211T213922, end_date=20241211T213927
[2024-12-11T18:39:27.874-0300] {standard_task_runner.py:110} ERROR - Failed to execute job 80 for task passo1 (An error occurred while calling o42.parquet.
: java.lang.RuntimeException: java.lang.ClassNotFoundException: Class org.apache.hadoop.fs.s3a.S3AFileSystem not found
	at org.apache.hadoop.conf.Configuration.getClass(Configuration.java:2688)
	at org.apache.hadoop.fs.FileSystem.getFileSystemClass(FileSystem.java:3431)
	at org.apache.hadoop.fs.FileSystem.createFileSystem(FileSystem.java:3466)
	at org.apache.hadoop.fs.FileSystem.access$300(FileSystem.java:174)
	at org.apache.hadoop.fs.FileSystem$Cache.getInternal(FileSystem.java:3574)
	at org.apache.hadoop.fs.FileSystem$Cache.get(FileSystem.java:3521)
	at org.apache.hadoop.fs.FileSystem.get(FileSystem.java:540)
	at org.apache.hadoop.fs.Path.getFileSystem(Path.java:365)
	at org.apache.spark.sql.execution.datasources.DataSource.planForWritingFileFormat(DataSource.scala:454)
	at org.apache.spark.sql.execution.datasources.DataSource.planForWriting(DataSource.scala:530)
	at org.apache.spark.sql.DataFrameWriter.saveToV1Source(DataFrameWriter.scala:391)
	at org.apache.spark.sql.DataFrameWriter.saveInternal(DataFrameWriter.scala:364)
	at org.apache.spark.sql.DataFrameWriter.save(DataFrameWriter.scala:243)
	at org.apache.spark.sql.DataFrameWriter.parquet(DataFrameWriter.scala:802)
	at java.base/jdk.internal.reflect.NativeMethodAccessorImpl.invoke0(Native Method)
	at java.base/jdk.internal.reflect.NativeMethodAccessorImpl.invoke(NativeMethodAccessorImpl.java:62)
	at java.base/jdk.internal.reflect.DelegatingMethodAccessorImpl.invoke(DelegatingMethodAccessorImpl.java:43)
	at java.base/java.lang.reflect.Method.invoke(Method.java:566)
	at py4j.reflection.MethodInvoker.invoke(MethodInvoker.java:244)
	at py4j.reflection.ReflectionEngine.invoke(ReflectionEngine.java:374)
	at py4j.Gateway.invoke(Gateway.java:282)
	at py4j.commands.AbstractCommand.invokeMethod(AbstractCommand.java:132)
	at py4j.commands.CallCommand.execute(CallCommand.java:79)
	at py4j.ClientServerConnection.waitForCommands(ClientServerConnection.java:182)
	at py4j.ClientServerConnection.run(ClientServerConnection.java:106)
	at java.base/java.lang.Thread.run(Thread.java:829)
Caused by: java.lang.ClassNotFoundException: Class org.apache.hadoop.fs.s3a.S3AFileSystem not found
	at org.apache.hadoop.conf.Configuration.getClassByName(Configuration.java:2592)
	at org.apache.hadoop.conf.Configuration.getClass(Configuration.java:2686)
	... 25 more
; 51305)
[2024-12-11T18:39:27.913-0300] {local_task_job_runner.py:240} INFO - Task exited with return code 1
[2024-12-11T18:39:27.928-0300] {taskinstance.py:3482} INFO - 0 downstream tasks scheduled from follow-on schedule check
[2024-12-11T18:39:27.933-0300] {local_task_job_runner.py:222} INFO - ::endgroup::
