[2024-12-09T15:58:03.688-0300] {local_task_job_runner.py:120} INFO - ::group::Pre task execution logs
[2024-12-09T15:58:03.705-0300] {taskinstance.py:2073} INFO - Dependencies all met for dep_context=non-requeueable deps ti=<TaskInstance: medallion_architecture.passo1 scheduled__2024-12-08T00:00:00+00:00 [queued]>
[2024-12-09T15:58:03.712-0300] {taskinstance.py:2073} INFO - Dependencies all met for dep_context=requeueable deps ti=<TaskInstance: medallion_architecture.passo1 scheduled__2024-12-08T00:00:00+00:00 [queued]>
[2024-12-09T15:58:03.712-0300] {taskinstance.py:2303} INFO - Starting attempt 1 of 1
[2024-12-09T15:58:03.726-0300] {taskinstance.py:2327} INFO - Executing <Task(PythonOperator): passo1> on 2024-12-08 00:00:00+00:00
[2024-12-09T15:58:03.730-0300] {clientserver.py:543} INFO - Closing down clientserver connection
[2024-12-09T15:58:03.730-0300] {standard_task_runner.py:63} INFO - Started process 12656 to run task
[2024-12-09T15:58:03.734-0300] {standard_task_runner.py:90} INFO - Running: ['airflow', 'tasks', 'run', 'medallion_architecture', 'passo1', 'scheduled__2024-12-08T00:00:00+00:00', '--job-id', '3', '--raw', '--subdir', 'DAGS_FOLDER/dag2.py', '--cfg-path', '/tmp/tmpxcf1to7w']
[2024-12-09T15:58:03.735-0300] {standard_task_runner.py:91} INFO - Job 3: Subtask passo1
[2024-12-09T15:58:03.767-0300] {task_command.py:426} INFO - Running <TaskInstance: medallion_architecture.passo1 scheduled__2024-12-08T00:00:00+00:00 [running]> on host beatriz-linux
[2024-12-09T15:58:03.827-0300] {taskinstance.py:2644} INFO - Exporting env vars: AIRFLOW_CTX_DAG_OWNER='airflow' AIRFLOW_CTX_DAG_ID='medallion_architecture' AIRFLOW_CTX_TASK_ID='passo1' AIRFLOW_CTX_EXECUTION_DATE='2024-12-08T00:00:00+00:00' AIRFLOW_CTX_TRY_NUMBER='1' AIRFLOW_CTX_DAG_RUN_ID='scheduled__2024-12-08T00:00:00+00:00'
[2024-12-09T15:58:03.828-0300] {taskinstance.py:430} INFO - ::endgroup::
[2024-12-09T15:58:03.907-0300] {clientserver.py:505} INFO - Error while sending or receiving.
Traceback (most recent call last):
  File "/home/beatriz/Documentos/airflow/airflow_venv/lib/python3.10/site-packages/py4j/clientserver.py", line 503, in send_command
    self.socket.sendall(command.encode("utf-8"))
ConnectionResetError: [Errno 104] Connection reset by peer
[2024-12-09T15:58:03.913-0300] {clientserver.py:543} INFO - Closing down clientserver connection
[2024-12-09T15:58:03.914-0300] {java_gateway.py:1052} INFO - Exception while sending command.
Traceback (most recent call last):
  File "/home/beatriz/Documentos/airflow/airflow_venv/lib/python3.10/site-packages/py4j/clientserver.py", line 503, in send_command
    self.socket.sendall(command.encode("utf-8"))
ConnectionResetError: [Errno 104] Connection reset by peer

During handling of the above exception, another exception occurred:

Traceback (most recent call last):
  File "/home/beatriz/Documentos/airflow/airflow_venv/lib/python3.10/site-packages/py4j/java_gateway.py", line 1038, in send_command
    response = connection.send_command(command)
  File "/home/beatriz/Documentos/airflow/airflow_venv/lib/python3.10/site-packages/py4j/clientserver.py", line 506, in send_command
    raise Py4JNetworkError(
py4j.protocol.Py4JNetworkError: Error while sending
[2024-12-09T15:58:03.916-0300] {clientserver.py:543} INFO - Closing down clientserver connection
[2024-12-09T15:58:13.608-0300] {python.py:237} INFO - Done. Returned value was: None
[2024-12-09T15:58:13.609-0300] {taskinstance.py:441} INFO - ::group::Post task execution logs
[2024-12-09T15:58:13.614-0300] {taskinstance.py:1205} INFO - Marking task as SUCCESS. dag_id=medallion_architecture, task_id=passo1, execution_date=20241208T000000, start_date=20241209T185803, end_date=20241209T185813
[2024-12-09T15:58:13.659-0300] {local_task_job_runner.py:240} INFO - Task exited with return code 0
[2024-12-09T15:58:13.676-0300] {taskinstance.py:3482} INFO - 1 downstream tasks scheduled from follow-on schedule check
[2024-12-09T15:58:13.681-0300] {local_task_job_runner.py:222} INFO - ::endgroup::
